Workbook
Name UPDATE: 'Data Sheet'!$E$1

Sheet Cash Flow Data
B2: 42339 | C2: 42705 | D2: 43070 | E2: 43435 | F2: 43800 | G2: 44166 | H2: 44531 | I2: 44896 | J2: 45261 | K2: 45352 | L2: 45717 | M2: 46082
B3: Cash from Operating Activity - | C3: 1098 | D3: 1466 | E3: 1818 | F3: 2052 | G3: 2295 | H3: 2454 | I3: 2236 | J3: 2737 | K3: 3392 | L3: 4175 | M3: 2935 | N3: 5048
B4: Profit from operations | C4: 1109 | D4: 1765 | E4: 2047 | F4: 2521 | G4: 2805 | H4: 3061 | I4: 3136 | J4: 3609 | K4: 4388 | L4: 5722 | M4: 4672 | N4: 5326
B5: Receivables | C5: 21 | D5: -19 | E5: 8 | F5: -36 | G5: 0 | H5: -42 | I5: -2 | J5: -28 | K5: -11 | L5: -109 | M5: -70 | N5: 34
B6: Inventory | C6: 23 | D6: -119 | E6: 38 | F6: -63 | G6: -318 | H6: -133 | I6: -169 | J6: -336 | K6: 56 | L6: -161 | M6: -767 | N6: 281
B7: Payables | C7: 79 | D7: 50 | E7: 185 | F7: 257 | G7: 253 | H7: 23 | I7: 217 | J7: 178 | K7: 68 | L7: 310 | M7: 134 | N7: 588
B8: Loans Advances | C8: -3 | D8: 0 | E8: 0 | F8: 0 | G8: 0 | H8: 0 | I8: -40 | J8: -30 | K8: -30 | L8: -21 | M8: -199 | N8: -73
B9: Operating borrowings | C9: 2 | D9: 0 | E9: 0 | F9: 0 | G9: 0 | H9: 0 | I9: 0 | J9: 0 | K9: 0 | L9: 0 | M9: 0 | N9: 0
B10: Other WC items | C10: 210 | D10: 293 | E10: 144 | F10: 255 | G10: 227 | H10: 249 | I10: -179 | J10: 185 | K10: -19 | L10: -268 | M10: 155 | N10: -37
B11: Working capital changes | C11: 332 | D11: 204 | E11: 375 | F11: 413 | G11: 163 | H11: 97 | I11: -172 | J11: -30 | K11: 63 | L11: -249 | M11: -747 | N11: 793
B12: Direct taxes | C12: -342 | D12: -503 | E12: -604 | F12: -881 | G12: -673 | H12: -703 | I12: -729 | J12: -841 | K12: -1059 | L12: -1299 | M12: -990 | N12: -1071
B13: Cash from Investing Activity - | C13: -70 | D13: -126 | E13: -131 | F13: -52 | G13: 83 | H13: -321 | I13: -1920 | J13: -392 | K13: -927 | L13: -1237 | M13: -1811 | N13: -624
B14: Fixed assets purchased | C14: -151 | D14: -207 | E14: -199 | F14: -166 | G14: -155 | H14: -478 | I14: -735 | J14: -550 | K14: -1371 | L14: -1883 | M14: -2009 | N14: -830
... B32: CFO/OP | C32: 0.93 | D32: 1.06 | E32: 1.16 | F32: 1.12 | G32: 1.01 | H32: 0.99 | I32: 0.83 | J32: 0.97 | K32: 1 | L32: 0.94 | M32: 0.82 | N32: 1.15

Sheet Company Flows
B2: Valuation | D2: Financial Modeling Forecast | J2: Forecast Income Statement | N2: Forecast Balance Sheet | R2: Forecast Cash Flow | V2: calculate Free Cash Flow
AA3: Where Forecasting Actually Happens
N4: Revenue
B5: Choose a Company | D5: Annual Report | J5: Revenue | N5: │ | R5: Net Income | V5: EBIT
B6: │ | D6: │ | J6: │ | N6: ▼ | R6: │ | V6: │ | AA6: Financial Statement | AB6: Forecast Driver
B7: ▼ | D7: ▼ | J7: ▼ | N7: Accounts Receivable | R7: ▼ | V7: ▼ | AA7: Revenue | AB7: Growth %, Volume × Price
B8: Read Annual Report | D8: Understand the Business Model | J8: Revenue Growth Assumption | N8: (Receivable Days) | R8: Add: Depreciation | V8: Less Tax | AA8: COGS | AB8: % of Revenue
B9: │ | D9: (Revenue, Products, Industry, Risks, Competition) | J9: │ | V9: │ | AA9: Marketing | AB9: % of Revenue
B10: ▼ | D10: │ | J10: ▼ | N10: Revenue | R10: ± Working Capital Changes | V10: ▼ | AA10: Employee Cost | AB10: % of Revenue or Headcount
B11: Understand Business | D11: ▼ | J11: Forecast Revenue | N11: │ | V11: NOPAT | AA11: Depreciation | AB11: PPE Schedule
B12: • Revenue | D12: Collect Historical Financial Data | J12: │ | N12: ▼ | R12: − Capex | V12: │ | AA12: Interest | AB12: Debt Schedule
B13: • Products | D13: (Income Statement, BS, Cash Flow) | J13: ▼ | N13: Inventory | V13: ▼ | AA13: Tax | AB13: Effective Tax Rate
B14: • Risks | D14: │ | J14: COGS (% of Revenue) | N14: (Inventory Days) | R14: ± Debt Raised/Repaid | V14: Add: Depreciation | AA14: Accounts Receivable | AB14: Receivable Days
B15: • Industry | D15: ▼ | J15: │ | V15: │ | AA15: Inventory | AB15: Inventory Days
B16: │ | D16: Clean & Structure Data in Excel | J16: ▼ | N16: COGS | R16: ± Dividends | V16: ▼ | AA16: Accounts Payable | AB16: Payable Days
B17: ▼ | D17: │ | J17: Gross Profit | N17: │ | V17: − Capex | AA17: PPE | AB17: Capex − Depreciation
B18: Historical Financial Statements | D18: ▼ | J18: │ | N18: ▼ | R18: ─────────────── | V18: │ | AA18: Cash | AB18: Cash Flow Statement
B19: (IS, BS, CFS) | D19: Historical Ratio Analysis | J19: ▼ | N19: Accounts Payable | R19: Ending Cash | V19: ▼
B20: │ | D20: (Margins, Growth, Working Capital, | J20: Operating Expenses | N20: (Payable Days) | V20: − Increase in Working Capital
B21: ▼ | D21: Liquidity, Leverage, Efficiency) | J21: (SG&A, Marketing, R&D) | V21: │
B22: Financial Modeling | D22: │ | J22: │ | N22: Capex | V22: ▼ | AA22: The 10-Step Formula You Should Memorize
B23: Forecast next 5–10 years | D23: ▼ | J23: ▼ | N23: │ | V23: Free Cash Flow (FCFF)
B24: • Revenue | D24: Identify Forecast Drivers | J24: EBITDA | N24: ▼ | AA24: 1. Understand the Business
B25: • Expenses | J25: │ | N25: PPE | AA25: 2. Collect Historical Financial Statements
B26: • Capex | J26: ▼ | AA26: 3. Perform Ratio & Trend Analysis
B27: • Working Capital | J27: Depreciation | N27: Debt Schedule | AA27: 4. Identify Forecast Drivers
B28: • Taxes | J28: │ | N28: │ | AA28: 5. Forecast Income Statement
B29: │ | J29: ▼ | N29: ▼ | AA29: 6. Forecast Balance Sheet
B30: ▼ | J30: EBIT | N30: Short-term Debt | V30: 46212 | AA30: 7. Forecast Cash Flow Statement
B31: Calculate Free Cash Flow (FCFF) | J31: │ | AA31: 8. Calculate Free Cash Flow (FCFF)
B32: │ | J32: ▼ | N32: Long-term Debt | AA32: 9. Value the Company (CAPM → WACC → DCF)
B33: ▼ | J33: Interest Expense | AA33: 10. Present Investment Recommendation
B34: Now ask... | J34: (Based on Debt) | N34: Retained Earnings
B35: What discount rate should I use? | J35: │ | N35: (Net Income − Dividend)
B36: │ | J36: ▼
B37: ▼ | J37: EBT | N37: Everything balances
B38: Calculate WACC | J38: │
B39: │ | J39: ▼ | N39: Assets = Liabilities + Equity
B40: ├──────────────┐ | J40: Tax
B41: ▼ ▼ | J41: │
...

Sheet WACC (2)
B6: Nestlee - Weighted Average Cost of Capital
B8: All figures are in INR unless stated otherwise
B10: Peer Companies
G12: Debt/ | H12: Debt/ | I12: Levered | J12: Unlevered
B13: Name of the Company | C13: Country | D13: Total Debt | E13: Total Equity | F13: Tax Rate1 | G13: Equity | H13: Capital | I13: Beta2 | J13: Beta3
B15: Nestle India | C15: India | D15: 444.16 | E15: 280608.3 | F15: 0.3 | G15: =D15/E15 -> 0.001582847 | H15: =D15/(D15+E15) -> 0.0015803455 | I15: 0.788 | J15: =I15/(1+(1-F15)*G15) -> 0.78712787
B16: Hind. Unilever | C16: India | D16: 1478 | E16: 505303.1 | F16: 0.3 | G16: =D16/E16 -> 0.0029249771 | H16: =D16/(D16+E16) -> 0.0029164466 | I16: 0.504 | J16: =I16/(1+(1-F16)*G16) -> 0.50297018
B17: Britannia Inds. | C17: India | D17: 1380.28 | E17: 128936.8 | F17: 0.3 | G17: =D17/E17 -> 0.01070509 | H17: =D17/(D17+E17) -> 0.010591704 | I17: 0.372 | J17: =I17/(1+(1-F17)*G17) -> 0.36923313
B18: Godrej Consumer | C18: India | D18: 4415.81 | E18: 111376.51 | F18: 0.3 | G18: =D18/E18 -> 0.039647588 | H18: =D18/(D18+E18) -> 0.038135603 | I18: 1.04 | J18: =I18/(1+(1-F18)*G18) -> 1.011916
B19: Tata Consumer | C19: India | D19: 2819.51 | E19: 110039.4 | F19: 0.3 | G19: =D19/E19 -> 0.025622731 | H19: =D19/(D19+E19) -> 0.024982609 | I19: 0.426 | J19: =I19/(1+(1-F19)*G19) -> 0.41849393
B20: Dabur India | C20: India | D20: 1287.32 | E20: 78674.79 | F20: 0.3 | G20: =D20/E20 -> 0.016362548 | H20: =D20/(D20+E20) -> 0.016099125 | I20: 0.927 | J20: =I20/(1+(1-F20)*G20) -> 0.91650258
E23: Average | F23: =AVERAGE(F15:F20) -> 0.3 | G23: =AVERAGE(G16:G20) -> 0.019052587 | H23: =AVERAGE(H16:H20) -> 0.018545098 | I23: =AVERAGE(I15:I20) -> 0.67616667 | J23: =AVERAGE(J15:J20) -> 0.66770728
E24: Median | F24: =MEDIAN(F15:F20) -> 0.3 | G24: =MEDIAN(G16:G20) -> 0.016362548 | H24: =MEDIAN(H16:H20) -> 0.016099125 | I24: =MEDIAN(I15:I20) -> 0.646 | J24: =MEDIAN(J15:J20) -> 0.64504902
B27: Cost of Debt | G27: Cost of Equity ( CAPM or Ke)
B29: Pre Tax Cost of Debt | D29: =37/D15 -> 0.083303314 | E29: >> Interest/Total Debt | G29: Risk Free Rate | K29: 0.06716 | L29: >>> 10 years Govt bond return
B30: Tax Rate | D30: =F15 -> 0.3 | G30: Equity Risk Premium | K30: =Rm!I5-'WACC (2)'!K29 -> 0.084332308 | L30: >> Rm- Rf = Rewarded Return
B31: Actual debt after Tax | D31: =D29*(1-D30) -> 0.05831232 | G31: Levered Beta4 | K31: =K40 -> 0.653581
G32: Cost of Equity | K32: =K29+K30*K31 -> 0.12227799
B35: Capital Structure | G35: Levered Beta
D37: Current | E37: Targeted | G37: Comps median unlevered beta | K37: =J24 -> 0.64504902
B38: Total Debt | C38: =D15 -> 444.16 | D38: =C38/C40 -> 0.0015803455 | E38: =H23 -> 0.018545098 | G38: Targeted debt/Equity | K38: =E43 -> 0.018895517
B39: Market Capitalization | C39: =E15 -> 280608.3 | D39: =C39/C40 -> 0.99841965 | E39: =E40-E38 -> 0.9814549 | G39: Tax Rate | K39: =D30 -> 0.3
B40: Total Capital | C40: =SUM(C38:C39) -> 281052.46 | D40: =SUM(D38:D39) -> 1 | E40: =D40 -> 1 | G40: Levered Beta | K40: =K37*(1+(1-K39)*K38) -> 0.653581
B43: Debt/Equity | D43: =D38/D39 -> 0.001582847 | E43: =E38/E39 -> 0.018895517 | G43: WACC
G44: Cost of Debt | K44: =D31 -> 0.05831232 | L44: Notes:
B45: Unlevered beta means business risk only | G45: Weight of Debt | K45: =E38 -> 0.018545098 | L45: Nifty 50 From Prime Investors finding out Rm
B46: Levered beta means business risk and financial risk | G46: Cost of Equity | K46: =K32 -> 0.12227799 | L46: Companies + Beta 1 year weekly return in Top Stock Research
B47: 1. Tax Rate considered as Marginal Tax Rate for the country | G47: Weight of Equity | K47: =E39 -> 0.9814549 | L47: Peer Companies with same business model, market cap from Screener
B48: 2. Levered Beta is based on 5 year monthly data | G48: Final | K48: =(K44*K45)+(K46*K47) -> 0.12109174 | L48: WACC >> Cost of money used by company
B49: 3. Unlevered Beta = Levered Beta/(1+(1-Tax Rate) x Debt/Equity)
B50: 4. Levered Beta = Unlevered Beta*(1+(1-Tax Rate) x Debt/Equity)

Sheet Data Sheet
A1: COMPANY NAME | B1: NESTLE INDIA LTD | E1: =IF(B2<>B3, "A NEW VERSION OF THE WORKSHEET IS AVAILABLE", "")
A2: LATEST VERSION | B2: 2.1 | E2: PLEASE DO NOT MAKE ANY CHANGES TO THIS SHEET
A3: CURRENT VERSION | B3: 2.1
A5: META
A6: Number of shares | B6: =IF(B9>0, B9/B8, 0) -> 192.83146
A7: Face Value | B7: 1
A8: Current Price | B8: 1409
A9: Market Capitalization | B9: 271699.53
A15: PROFIT & LOSS
A16: Report Date | B16: 43100 | C16: 43465 | D16: 43830 | E16: 44196 | F16: 44561 | G16: 44926 | H16: 45291 | I16: 45382 | J16: 45747 | K16: 46112
A17: Sales | B17: 10009.6 | C17: 11292.27 | D17: 12368.9 | E17: 13350.03 | F17: 14740.59 | G17: 16896.96 | H17: 19126.3 | I17: 24393.89 | J17: 20201.56 | K17: 23154.6
A18: Raw Material Cost | B18: 3696.99 | C18: 3829.22 | D18: 4520.91 | E18: 4901.74 | F18: 5301.26 | G18: 6660.42 | H18: 8472.72 | I18: 9201.11 | J18: 7646.63 | K18: 9113.96
A19: Change in Inventory | B19: 79.56 | C19: 6.01 | D19: 144.19 | E19: 69.33 | F19: 67.59 | G19: 250.27 | H19: 40.01 | I19: 45.68 | J19: 139.66 | K19: 168.23
A20: Power and Fuel | B20: 288.44 | C20: 344.18 | D20: 340.53 | E20: 313.68 | F20: 408.06 | G20: 572.61 | I20: 674.83 | J20: 541.42 | K20: 587.21
A21: Other Mfr. Exp | B21: 897.84 | C21: 949.86 | D21: 1028.55 | E21: 1040.36 | F21: 1349.48 | G21: 1603.48 | I21: 1935.4 | J21: 1582.45 | K21: 1816.29
A22: Employee Cost | B22: 1017.45 | C22: 1124.15 | D22: 1258.17 | E22: 1500.95 | F22: 1529.94 | G22: 1635.46 | H22: 1849.18 | I22: 2336.06 | J22: 2062.02 | K22: 2278.41
A23: Selling and admin | B23: 1823.98 | C23: 2145.82 | D23: 2226.13 | E23: 2246.9 | F23: 2902.12 | G23: 3192.15 | I23: 4837.58 | J23: 4126.54 | K23: 4780.9
A24: Other Expenses | B24: 267.93 | C24: 287.4 | D24: 212.92 | E24: 214.23 | F24: -245.08 | G24: -223.18 | H24: 4373.42 | I24: -388.53 | J24: -389.17 | K24: -560.9
A25: Other Income | B25: 176.92 | C25: 258.92 | D25: 246.88 | E25: 145.85 | F25: -112.38 | G25: 107.26 | H25: 115.5 | I25: 158.99 | J25: 352.06 | K25: 160.23
A26: Depreciation | B26: 342.25 | C26: 335.67 | D26: 370.15 | E26: 370.38 | F26: 391.02 | G26: 403.01 | H26: 428.91 | I26: 567.75 | J26: 539.92 | K26: 699.23
A27: Interest | B27: 91.9 | C27: 111.95 | D27: 129.12 | E27: 164.18 | F27: 201.68 | G27: 154.57 | H27: 119.29 | I27: 145.49 | J27: 136 | K27: 158.31
A28: Profit before tax | B28: 1839.3 | C28: 2428.95 | D28: 2673.49 | E28: 2812.79 | F28: 2857.32 | G28: 3255.97 | H28: 4038.29 | I28: 5288.87 | J28: 4447.47 | K28: 4609.65
A29: Tax | B29: 614.11 | C29: 822.02 | D29: 705.05 | E29: 730.36 | F29: 738.91 | G29: 865.45 | H29: 1039.62 | I29: 1356.03 | J29: 1132.97 | K29: 1065.05
A30: Net profit | B30: 1225.19 | C30: 1606.93 | D30: 1968.44 | E30: 2082.43 | F30: 2118.41 | G30: 2390.52 | H30: 2998.67 | I30: 3932.84 | J30: 3314.5 | K30: 3544.6
A31: Dividend Amount | B31: 829.21 | C31: 1108.83 | D31: 3297.56 | E31: 1928.4 | F31: 1928.4 | G31: 2121.24 | H31: 1677.71 | I31: 3104.72 | J31: 2603.34 | K31: 2313.96
A40: Quarters
A41: Report Date | B41: 45291 | C41: 45382 | D41: 45473 | E41: 45565 | F41: 45657 | G41: 45747 | H41: 45838 | I41: 45930 | J41: 46022 | K41: 46112
A42: Sales | B42: 4600.42 | C42: 5267.59 | D42: 4813.95 | E42: 5104 | F42: 4779.73 | G42: 5503.88 | H42: 5096.16 | I42: 5643.61 | J42: 5667.04 | K42: 6747.79
A43: Expenses | B43: 3505.3 | C43: 3917.54 | D43: 3699.62 | E43: 3936.27 | F43: 3677.04 | G43: 4115.58 | H43: 3995.9 | I43: 4406.97 | J43: 4466.09 | K43: 4976.19
A44: Other Income | B44: -77 | C44: 36.83 | D44: 39.12 | E44: 297.68 | F44: 4.44 | G44: 9.1 | H44: 4.04 | I44: 1.64 | J44: 169.78 | K44: -17.72
A45: Depreciation | B45: 108.69 | C45: 110.1 | D45: 112.71 | E45: 121.6 | F45: 150.27 | G45: 155.34 | H45: 156.94 | I45: 163.35 | J45: 174.41 | K45: 204.53
A46: Interest | B46: 22.95 | C46: 26.2 | D46: 31.68 | E46: 32.22 | F46: 34.6 | G46: 37.5 | H46: 46.89 | I46: 46.41 | J46: 28.25 | K46: 36.76
A47: Profit before tax | B47: 886.48 | C47: 1250.58 | D47: 1009.06 | E47: 1311.59 | F47: 922.26 | G47: 1204.56 | H47: 900.47 | I47: 1028.52 | J47: 1168.07 | K47: 1512.59
A48: Tax | B48: 230.87 | C48: 316.41 | D48: 262.46 | E48: 325.23 | F48: 226.13 | G48: 319.15 | H48: 241.24 | I48: 275.32 | J48: 150.01 | K48: 398.48
A49: Net profit | B49: 655.61 | C49: 934.17 | D49: 746.6 | E49: 986.36 | F49: 696.13 | G49: 885.41 | H49: 659.23 | I49: 753.2 | J49: 1018.06 | K49: 1114.11
A50: Operating Profit | B50: 1095.12 | C50: 1350.05 | D50: 1114.33 | E50: 1167.73 | F50: 1102.69 | G50: 1388.3 | H50: 1100.26 | I50: 1236.64 | J50: 1200.95 | K50: 1771.6
A55: BALANCE SHEET
A56: Report Date | B56: 43100 | C56: 43465 | D56: 43830 | E56: 44196 | F56: 44561 | G56: 44926 | H56: 45291 | I56: 45382 | J56: 45747 | K56: 46112
A57: Equity Share Capital | B57: 96.42 | C57: 96.42 | D57: 96.42 | E57: 96.42 | F57: 96.42 | G57: 96.42 | H57: 96.42 | I57: 96.42 | J57: 96.42 | K57: 192.83
A58: Reserves | B58: 3324.17 | C58: 3577.32 | D58: 1822.45 | E58: 1922.92 | F58: 1849.96 | G58: 2362.75 | H58: 2362.75 | I58: 3244.47 | J58: 4020.73 | K58: 5116.41
...

Sheet Historical Analysis
B7: =" Financial Statements - "&'Data Sheet'!B1 -> Financial Statements - NESTLE INDIA LTD
B8: Year | C8: ='Data Sheet'!B16 -> 43100 | D8: ='Data Sheet'!C16 -> 43465 | E8: ='Data Sheet'!D16 -> 43830 | F8: ='Data Sheet'!E16 -> 44196 | G8: ='Data Sheet'!F16 -> 44561 | H8: ='Data Sheet'!G16 -> 44926 | I8: ='Data Sheet'!H16 -> 45291 | J8: ='Data Sheet'!I16 -> 45382 | ... L8: ='Data Sheet'!K16 -> 46112
B9: wf
B10: Income Statement
A11: # | B11: Sales | C11: =IFERROR('Data Sheet'!B17,0) -> 10009.6 | D11: =IFERROR('Data Sheet'!C17,0) -> 11292.27 | E11: =IFERROR('Data Sheet'!D17,0) -> 12368.9 | F11: =IFERROR('Data Sheet'!E17,0) -> 13350.03 | G11: =IFERROR('Data Sheet'!F17,0) -> 14740.59 | H11: =IFERROR('Data Sheet'!G17,0) -> 16896.96 | I11: =IFERROR('Data Sheet'!H17,0) -> 19126.3 | J11: =IFERROR('Data Sheet'!I17,0) -> 24393.89 | ... L11: =IFERROR('Data Sheet'!K17,0) -> 23154.6
B12: Sales Growth | C12: - | D12: =D11/C11-1 -> 0.12814398 | E12: =E11/D11-1 -> 0.095342212 | F12: =F11/E11-1 -> 0.079322333 | G12: =G11/F11-1 -> 0.10416156 | H12: =H11/G11-1 -> 0.1462879 | I12: =I11/H11-1 -> 0.13193734 | J12: =J11/I11-1 -> 0.27541082 | K12: =K11/J11-1 -> -0.17185984 | L12: =L11/K11-1 -> 0.14617881
B13: COGS | C13: =IFERROR(SUM('Data Sheet'!B18,'Data Sheet'!B20:B22)-1*'Data Sheet'!B19,0) -> 5821.16 | D13: =IFERROR(SUM('Data Sheet'!C18,'Data Sheet'!C20:C22)-1*'Data Sheet'!C19,0) -> 6241.4 | E13: =IFERROR(SUM('Data Sheet'!D18,'Data Sheet'!D20:D22)-1*'Data Sheet'!D19,0) -> 7003.97 | F13: =IFERROR(SUM('Data Sheet'!E18,'Data Sheet'!E20:E22)-1*'Data Sheet'!E19,0) -> 7687.4 | G13: =IFERROR(SUM('Data Sheet'!F18,'Data Sheet'!F20:F22)-1*'Data Sheet'!F19,0) -> 8521.15 | H13: =IFERROR(SUM('Data Sheet'!G18,'Data Sheet'!G20:G22)-1*'Data Sheet'!G19,0) -> 10221.7 | I13: =IFERROR(SUM('Data Sheet'!H18,'Data Sheet'!H20:H22)-1*'Data Sheet'!H19,0) -> 10281.89 | J13: =IFERROR(SUM('Data Sheet'!I18,'Data Sheet'!I20:I22)-1*'Data Sheet'!I19,0) -> 14101.72 | ... L13: =IFERROR(SUM('Data Sheet'!K18,'Data Sheet'!K20:K22)-1*'Data Sheet'!K19,0) -> 13627.64
B14: COGS % Sales | C14: =C13/C11 -> 0.5815577 | D14: =D13/D11 -> 0.55271438 | E14: =E13/E11 -> 0.5662565 | F14: =F13/F11 -> 0.57583391 | G14: =G13/G11 -> 0.57807388 | H14: =H13/H11 -> 0.60494314 | I14: =I13/I11 -> 0.53757862 | J14: =J13/J11 -> 0.5780841 | ... L14: =L13/L11 -> 0.58855001
B16: Gross Profit | C16: =C11-C13 -> 4188.44 | D16: =D11-D13 -> 5050.87 | E16: =E11-E13 -> 5364.93 | F16: =F11-F13 -> 5662.63 | G16: =G11-G13 -> 6219.44 | H16: =H11-H13 -> 6675.26 | I16: =I11-I13 -> 8844.41 | J16: =J11-J13 -> 10292.17 | ... L16: =L11-L13 -> 9526.96
B18: Selling & General Exp | C18: =IFERROR('Data Sheet'!B23,0) -> 1823.98 | D18: =IFERROR('Data Sheet'!C23,0) -> 2145.82 | E18: =IFERROR('Data Sheet'!D23,0) -> 2226.13 | F18: =IFERROR('Data Sheet'!E23,0) -> 2246.9 | G18: =IFERROR('Data Sheet'!F23,0) -> 2902.12 | H18: =IFERROR('Data Sheet'!G23,0) -> 3192.15 | I18: =IFERROR('Data Sheet'!H23,0) -> 0 | J18: =IFERROR('Data Sheet'!I23,0) -> 4837.58 | ... L18: =IFERROR('Data Sheet'!K23,0) -> 4780.9
B19: S&G % on Sales | C19: =C18/C11 -> 0.18222307 | D19: =D18/D11 -> 0.19002557 | E19: =E18/E11 -> 0.17997801 | F19: =F18/F11 -> 0.16830674 | G19: =G18/G11 -> 0.1968795 | H19: =H18/H11 -> 0.1889186 | I19: =I18/I11 -> 0 | J19: =J18/J11 -> 0.19831113 | ... L19: =L18/L11 -> 0.20647733
B21: Other Exp | C21: =IFERROR('Data Sheet'!B24,0) -> 267.93 | D21: =IFERROR('Data Sheet'!C24,0) -> 287.4 | E21: =IFERROR('Data Sheet'!D24,0) -> 212.92 | F21: =IFERROR('Data Sheet'!E24,0) -> 214.23 | G21: =IFERROR('Data Sheet'!F24,0) -> -245.08 | H21: =IFERROR('Data Sheet'!G24,0) -> -223.18 | I21: =IFERROR('Data Sheet'!H24,0) -> 4373.42 | J21: =IFERROR('Data Sheet'!I24,0) -> -388.53 | ... L21: =IFERROR('Data Sheet'!K24,0) -> -560.9
B23: EBITDA | C23: =C16-C18-ABS(C21) -> 2096.53 | D23: =D16-D18-ABS(D21) -> 2617.65 | E23: =E16-E18-ABS(E21) -> 2925.88 | F23: =F16-F18-ABS(F21) -> 3201.5 | G23: =G16-G18-G21 -> 3562.4 | H23: =H16-H18-H21 -> 3706.29 | I23: =I16-I18-ABS(I21) -> 4470.99 | J23: =J16-J18-J21 -> 5843.12 | K23: =K16-K18-K21 -> 4771.33 | L23: =L16-L18-L21 -> 5306.96
B24: EBITDA % on sales | C24: =C23/C11 -> 0.20945193 | D24: =D23/D11 -> 0.23180902 | E24: =E23/E11 -> 0.23655135 | F24: =F23/F11 -> 0.2398122 | G24: =G23/G11 -> 0.24167282 | H24: =H23/H11 -> 0.21934656 | I24: =I23/I11 -> 0.23376137 | J24: =J23/J11 -> 0.23953211 | ... L24: =L23/L11 -> 0.22919679
B26: Other Income | C26: =IFERROR('Data Sheet'!B25,0) -> 176.92 | D26: =IFERROR('Data Sheet'!C25,0) -> 258.92 | E26: =IFERROR('Data Sheet'!D25,0) -> 246.88 | F26: =IFERROR('Data Sheet'!E25,0) -> 145.85 | G26: =IFERROR('Data Sheet'!F25,0) -> -112.38 | H26: =IFERROR('Data Sheet'!G25,0) -> 107.26 | I26: =IFERROR('Data Sheet'!H25,0) -> 115.5 | J26: =IFERROR('Data Sheet'!I25,0) -> 158.99 | ... L26: =IFERROR('Data Sheet'!K25,0) -> 160.23
B28: Depreciation | C28: =IFERROR('Data Sheet'!B26,0) -> 342.25 | D28: =IFERROR('Data Sheet'!C26,0) -> 335.67 | E28: =IFERROR('Data Sheet'!D26,0) -> 370.15 | F28: =IFERROR('Data Sheet'!E26,0) -> 370.38 | G28: =IFERROR('Data Sheet'!F26,0) -> 391.02 | H28: =IFERROR('Data Sheet'!G26,0) -> 403.01 | I28: =IFERROR('Data Sheet'!H26,0) -> 428.91 | J28: =IFERROR('Data Sheet'!I26,0) -> 567.75 | ... L28: =IFERROR('Data Sheet'!K26,0) -> 699.23
B29: Depreciation on sales | C29: =C28/C11 -> 0.034192176 | D29: =D28/D11 -> 0.029725644 | E29: =E28/E11 -> 0.029925862 | F29: =F28/F11 -> 0.027743758 | G29: =G28/G11 -> 0.026526754 | H29: =H28/H11 -> 0.023851036 | I29: =I28/I11 -> 0.022425142 | J29: =J28/J11 -> 0.023274271 | ... L29: =L28/L11 -> 0.030198319
B31: EBIT ( Operating Income) | C31: =C23+C26-C28 -> 1931.2 | D31: =D23+D26-D28 -> 2540.9 | E31: =E23+E26-E28 -> 2802.61 | F31: =F23+F26-F28 -> 2976.97 | G31: =G23+G26-G28 -> 3059 | H31: =H23+H26-H28 -> 3410.54 | I31: =I23+I26-I28 -> 4157.58 | J31: =J23+J26-J28 -> 5434.36 | ... L31: =L23+L26-L28 -> 4767.96
B33: Interest | C33: =IFERROR('Data Sheet'!B27,0) -> 91.9 | D33: =IFERROR('Data Sheet'!C27,0) -> 111.95 | E33: =IFERROR('Data Sheet'!D27,0) -> 129.12 | F33: =IFERROR('Data Sheet'!E27,0) -> 164.18 | G33: =IFERROR('Data Sheet'!F27,0) -> 201.68 | H33: =IFERROR('Data Sheet'!G27,0) -> 154.57 | I33: =IFERROR('Data Sheet'!H27,0) -> 119.29 | J33: =IFERROR('Data Sheet'!I27,0) -> 145.49 | ... L33: =IFERROR('Data Sheet'!K27,0) -> 158.31
B34: Interest % on sales | C34: =C33/C11 -> 0.0091811861 | D34: =D33/D11 -> 0.0099138614 | E34: =E33/E11 -> 0.010439085 | F34: =F33/F11 -> 0.0122981 | G34: =G33/G11 -> 0.013681949 | H34: =H33/H11 -> 0.0091477994 | I34: =I33/I11 -> 0.0062369617 | J34: =J33/J11 -> 0.0059641984 | ... L34: =L33/L11 -> 0.0068370864
B37: EBT | C37: =C31-C33 -> 1839.3 | D37: =D31-D33 -> 2428.95 | E37: =E31-E33 -> 2673.49 | F37: =F31-F33 -> 2812.79 | G37: =G31-G33 -> 2857.32 | H37: =H31-H33 -> 3255.97 | I37: =I31-I33 -> 4038.29 | J37: =J31-J33 -> 5288.87 | ... L37: =L31-L33 -> 4609.65
B38: EBT % on sales | C38: =C37/C11 -> 0.1837536 | D38: =D37/D11 -> 0.21509847 | E38: =E37/E11 -> 0.21614614 | F38: =F37/F11 -> 0.21069541 | G38: =G37/G11 -> 0.19384027 | H38: =H37/H11 -> 0.19269561 | I38: =I37/I11 -> 0.21113807 | J38: =J37/J11 -> 0.21681126 | ... L38: =L37/L11 -> 0.19908139
B41: TAX | C41: =IFERROR('Data Sheet'!B29,0) -> 614.11 | D41: =IFERROR('Data Sheet'!C29,0) -> 822.02 | E41: =IFERROR('Data Sheet'!D29,0) -> 705.05 | F41: =IFERROR('Data Sheet'!E29,0) -> 730.36 | G41: =IFERROR('Data Sheet'!F29,0) -> 738.91 | H41: =IFERROR('Data Sheet'!G29,0) -> 865.45 | I41: =IFERROR('Data Sheet'!H29,0) -> 1039.62 | J41: =IFERROR('Data Sheet'!I29,0) -> 1356.03 | ... L41: =IFERROR('Data Sheet'!K29,0) -> 1065.05
B42: Effective Tax Growth | C42: =C41/C37 -> 0.33388246 | D42: =D41/D37 -> 0.33842607 | E42: =E41/E37 -> 0.26371896 | F42: =F41/F37 -> 0.25965678 | G42: =G41/G37 -> 0.25860247 | H42: =H41/H37 -> 0.26580405 | I42: =I41/I37 -> 0.25744065 | J42: =J41/J37 -> 0.25639314 | ... L42: =L41/L37 -> 0.23104791
B44: Net Profit | C44: =IFERROR(C37-C41,0) -> 1225.19 | D44: =IFERROR(D37-D41,0) -> 1606.93 | E44: =IFERROR(E37-E41,0) -> 1968.44 | F44: =IFERROR(F37-F41,0) -> 2082.43 | G44: =IFERROR(G37-G41,0) -> 2118.41 | H44: =IFERROR(H37-H41,0) -> 2390.52 | I44: =IFERROR(I37-I41,0) -> 2998.67 | J44: =IFERROR(J37-J41,0) -> 3932.84 | ... L44: =IFERROR(L37-L41,0) -> 3544.6
B45: Net Profit % on sales/ Margins | C45: =C44/C11 -> 0.12240149 | D45: =D44/D11 -> 0.14230354 | E45: =E44/E11 -> 0.15914431 | F45: =F44/F11 -> 0.15598692 | G45: =G44/G11 -> 0.1437127 | H45: =H44/H11 -> 0.14147634 | I45: =I44/I11 -> 0.15678255 | J45: =J44/J11 -> 0.16122234 | ... L45: =L44/L11 -> 0.15308405
B47: No of Equity Shares | C47: =IFERROR('Data Sheet'!B93,0) -> 192.8 | D47: =IFERROR('Data Sheet'!C93,0) -> 192.8 | E47: =IFERROR('Data Sheet'!D93,0) -> 192.8 | F47: =IFERROR('Data Sheet'!E93,0) -> 192.8 | G47: =IFERROR('Data Sheet'!F93,0) -> 192.8 | H47: =IFERROR('Data Sheet'!G93,0) -> 192.8 | I47: =IFERROR('Data Sheet'!H93,0) -> 192.8 | J47: =IFERROR('Data Sheet'!I93,0) -> 192.83 | ... L47: =IFERROR('Data Sheet'!K93,0) -> 192.83
B49: EPS | C49: =IFERROR(C44/C47,0) -> 6.3547199 | D49: =IFERROR(D44/D47,0) -> 8.3346992 | E49: =IFERROR(E44/E47,0) -> 10.209751 | F49: =IFERROR(F44/F47,0) -> 10.800985 | G49: =IFERROR(G44/G47,0) -> 10.987604 | H49: =IFERROR(H44/H47,0) -> 12.398963 | I49: =IFERROR(I44/I47,0) -> 15.553268 | J49: =IFERROR(J44/J47,0) -> 20.395374 | ... L49: =IFERROR(L44/L47,0) -> 18.381995
B50: EPS Growth% | D50: =IFERROR(D49/C49-1,0) -> 0.31157616 | E50: =IFERROR(E49/D49-1,0) -> 0.22496935 | F50: =IFERROR(F49/E49-1,0) -> 0.057908801 | G50: =IFERROR(G49/F49-1,0) -> 0.017277892 | H50: =IFERROR(H49/G49-1,0) -> 0.12845011 | I50: =IFERROR(I49/H49-1,0) -> 0.25440072 | J50: =IFERROR(J49/I49-1,0) -> 0.31132407 | K50: =IFERROR(K49/J49-1,0) -> -0.1572248 | L50: =IFERROR(L49/K49-1,0) -> 0.069422236
B53: Dividend Per share | C53: =IFERROR('Data Sheet'!B31/'Historical Analysis'!C47,0) -> 4.3008817 | D53: =IFERROR('Data Sheet'!C31/'Historical Analysis'!D47,0) -> 5.7511929 | E53: =IFERROR('Data Sheet'!D31/'Historical Analysis'!E47,0) -> 17.103527 | F53: =IFERROR('Data Sheet'!E31/'Historical Analysis'!F47,0) -> 10.002075 | G53: =IFERROR('Data Sheet'!F31/'Historical Analysis'!G47,0) -> 10.002075 | H53: =IFERROR('Data Sheet'!G31/'Historical Analysis'!H47,0) -> 11.002282 | I53: =IFERROR('Data Sheet'!H31/'Historical Analysis'!I47,0) -> 8.7018154 | J53: =IFERROR('Data Sheet'!I31/'Historical Analysis'!J47,0) -> 16.100814 | ... L53: =IFERROR('Data Sheet'!K31/'Historical Analysis'!L47,0) -> 12
B54: Dividend Payout ratio | C54: =C53/C49 -> 0.67680115 | D54: =D53/D49 -> 0.69003006 | E54: =E53/E49 -> 1.6752149 | F54: =F53/F49 -> 0.92603353 | G54: =G53/G49 -> 0.91030537 | H54: =H53/H49 -> 0.88735505 | I54: =I53/I49 -> 0.5594847 | J54: =J53/J49 -> 0.78943461 | ... L54: =L53/L49 -> 0.65281273
C55: =IFERROR(C53/C49,0) -> 0.67680115 | D55: =IFERROR(D53/D49,0) -> 0.69003006 | E55: =IFERROR(E53/E49,0) -> 1.6752149 | F55: =IFERROR(F53/F49,0) -> 0.92603353 | G55: =IFERROR(G53/G49,0) -> 0.91030537 | H55: =IFERROR(H53/H49,0) -> 0.88735505 | I55: =IFERROR(I53/I49,0) -> 0.5594847 | J55: =IFERROR(J53/J49,0) -> 0.78943461 | ... L55: =IFERROR(L53/L49,0) -> 0.65281273
B57: Retained Earning ( Retention Ratio) | C57: =IFERROR(IF(C49>C53,1-C54,0),0) -> 0.32319885 | D57: =IFERROR(IF(D49>D53,1-D54,0),0) -> 0.30996994 | E57: =IFERROR(IF(E49>E53,1-E54,0),0) -> 0 | F57: =IFERROR(IF(F49>F53,1-F54,0),0) -> 0.073966472 | G57: =IFERROR(IF(G49>G53,1-G54,0),0) -> 0.089694629 | H57: =IFERROR(IF(H49>H53,1-H54,0),0) -> 0.11264495 | I57: =IFERROR(IF(I49>I53,1-I54,0),0) -> 0.4405153 | J57: =IFERROR(IF(J49>J53,1-J54,0),0) -> 0.21056539 | ... L57: =IFERROR(IF(L49>L53,1-L54,0),0) -> 0.34718727
C58: =C57+C55 -> 1 | D58: =D57+D55 -> 1 | E58: =E57+E55 -> 1.6752149 | F58: =F57+F55 -> 1 | G58: =G57+G55 -> 1 | H58: =H57+H55 -> 1 | I58: =I57+I55 -> 1 | J58: =J57+J55 -> 1 | ... L58: =L57+L55 -> 1
B59: Retention Ratio | C59: =1-C54 -> 0.32319885 | D59: =1-D54 -> 0.30996994 | E59: =1-E54 -> -0.67521489 | F59: =1-F54 -> 0.073966472 | G59: =1-G54 -> 0.089694629 | H59: =1-H54 -> 0.11264495 | I59: =1-I54 -> 0.4405153 | J59: =1-J54 -> 0.21056539 | ... L59: =1-L54 -> 0.34718727
A61: # | B61: Balance Sheet
B63: Equity Share Capital | C63: =IFERROR('Data Sheet'!B57,0) -> 96.42 | D63: =IFERROR('Data Sheet'!C57,0) -> 96.42 | E63: =IFERROR('Data Sheet'!D57,0) -> 96.42 | F63: =IFERROR('Data Sheet'!E57,0) -> 96.42 | G63: =IFERROR('Data Sheet'!F57,0) -> 96.42 | H63: =IFERROR('Data Sheet'!G57,0) -> 96.42 | I63: =IFERROR('Data Sheet'!H57,0) -> 96.42 | J63: =IFERROR('Data Sheet'!I57,0) -> 96.42 | ... L63: =IFERROR('Data Sheet'!K57,0) -> 192.83
B64: Reserves | C64: =IFERROR('Data Sheet'!B58,0) -> 3324.17 | D64: =IFERROR('Data Sheet'!C58,0) -> 3577.32 | E64: =IFERROR('Data Sheet'!D58,0) -> 1822.45 | F64: =IFERROR('Data Sheet'!E58,0) -> 1922.92 | G64: =IFERROR('Data Sheet'!F58,0) -> 1849.96 | H64: =IFERROR('Data Sheet'!G58,0) -> 2362.75 | I64: =IFERROR('Data Sheet'!H58,0) -> 2362.75 | J64: =IFERROR('Data Sheet'!I58,0) -> 3244.47 | ... L64: =IFERROR('Data Sheet'!K58,0) -> 5116.41
B65: Borrowings | C65: =IFERROR('Data Sheet'!B59,0) -> 35.14 | D65: =IFERROR('Data Sheet'!C59,0) -> 35.14 | E65: =IFERROR('Data Sheet'!D59,0) -> 188.94 | F65: =IFERROR('Data Sheet'!E59,0) -> 147.49 | G65: =IFERROR('Data Sheet'!F59,0) -> 266.46 | H65: =IFERROR('Data Sheet'!G59,0) -> 270.52 | I65: =IFERROR('Data Sheet'!H59,0) -> 270.52 | J65: =IFERROR('Data Sheet'!I59,0) -> 344.53 | ... L65: =IFERROR('Data Sheet'!K59,0) -> 444.16
B66: Other Liabilities | C66: =IFERROR('Data Sheet'!B60,0) -> 3906.86 | D66: =IFERROR('Data Sheet'!C60,0) -> 4379.2 | E66: =IFERROR('Data Sheet'!D60,0) -> 5065.13 | F66: =IFERROR('Data Sheet'!E60,0) -> 5732.9 | G66: =IFERROR('Data Sheet'!F60,0) -> 6021.29 | H66: =IFERROR('Data Sheet'!G60,0) -> 6249.05 | I66: =IFERROR('Data Sheet'!H60,0) -> 6249.05 | J66: =IFERROR('Data Sheet'!I60,0) -> 6837.64 | ... L66: =IFERROR('Data Sheet'!K60,0) -> 7603.77
...

Sheet Ratio Analysis
B7: =" Ratio Analysis - "&'Data Sheet'!B1 -> Ratio Analysis - NESTLE INDIA LTD
B8: Year | C8: ='Data Sheet'!B16 -> 43100 | D8: ='Data Sheet'!C16 -> 43465 | E8: ='Data Sheet'!D16 -> 43830 | F8: ='Data Sheet'!E16 -> 44196 | G8: ='Data Sheet'!F16 -> 44561 | H8: ='Data Sheet'!G16 -> 44926 | I8: ='Data Sheet'!H16 -> 45291 | J8: ='Data Sheet'!I16 -> 45382 | ... L8: ='Data Sheet'!K16 -> 46112 | M8: Trend Analysis | N8: Mean | O8: Median
B10: SalesGrowth | D10: =IFERROR('Historical Analysis'!D12,0) -> 0.12814398 | E10: =IFERROR('Historical Analysis'!E12,0) -> 0.095342212 | F10: =IFERROR('Historical Analysis'!F12,0) -> 0.079322333 | G10: =IFERROR('Historical Analysis'!G12,0) -> 0.10416156 | H10: =IFERROR('Historical Analysis'!H12,0) -> 0.1462879 | I10: =IFERROR('Historical Analysis'!I12,0) -> 0.13193734 | J10: =IFERROR('Historical Analysis'!J12,0) -> 0.27541082 | K10: =IFERROR('Historical Analysis'!K12,0) -> -0.17185984 | L10: =IFERROR('Historical Analysis'!L12,0) -> 0.14617881 | N10: =IFERROR(AVERAGE(D10:L10),0) -> 0.10388057 | O10: =MEDIAN(D10:L10) -> 0.12814398
B11: EBITDA Growth | D11: =IFERROR('Historical Analysis'!D23/'Historical Analysis'!C23-1,0) -> 0.2485631 | E11: =IFERROR('Historical Analysis'!E23/'Historical Analysis'!D23-1,0) -> 0.11775065 | F11: =IFERROR('Historical Analysis'!F23/'Historical Analysis'!E23-1,0) -> 0.094200719 | G11: =IFERROR('Historical Analysis'!G23/'Historical Analysis'!F23-1,0) -> 0.11272841 | H11: =IFERROR('Historical Analysis'!H23/'Historical Analysis'!G23-1,0) -> 0.040391309 | I11: =IFERROR('Historical Analysis'!I23/'Historical Analysis'!H23-1,0) -> 0.20632492 | J11: =IFERROR('Historical Analysis'!J23/'Historical Analysis'!I23-1,0) -> 0.30689624 | K11: =IFERROR('Historical Analysis'!K23/'Historical Analysis'!J23-1,0) -> -0.18342769 | L11: =IFERROR('Historical Analysis'!L23/'Historical Analysis'!K23-1,0) -> 0.1122601 | N11: =IFERROR(AVERAGE(D11:L11),0) -> 0.11729864 | O11: =MEDIAN(D11:L11) -> 0.11272841
B12: EBIT Growth | D12: =IFERROR('Historical Analysis'!D31/'Historical Analysis'!C31-1,0) -> 0.31571044 | E12: =IFERROR('Historical Analysis'!E31/'Historical Analysis'!D31-1,0) -> 0.10299894 | F12: =IFERROR('Historical Analysis'!F31/'Historical Analysis'!E31-1,0) -> 0.062213437 | G12: =IFERROR('Historical Analysis'!G31/'Historical Analysis'!F31-1,0) -> 0.027554863 | H12: =IFERROR('Historical Analysis'!H31/'Historical Analysis'!G31-1,0) -> 0.11491991 | I12: =IFERROR('Historical Analysis'!I31/'Historical Analysis'!H31-1,0) -> 0.21903863 | J12: =IFERROR('Historical Analysis'!J31/'Historical Analysis'!I31-1,0) -> 0.30709692 | K12: =IFERROR('Historical Analysis'!K31/'Historical Analysis'!J31-1,0) -> -0.15657594 | L12: =IFERROR('Historical Analysis'!L31/'Historical Analysis'!K31-1,0) -> 0.040251163 | N12: =IFERROR(AVERAGE(D12:L12),0) -> 0.11480093 | O12: =MEDIAN(D12:L12) -> 0.10299894
B13: Net Profit Growth | D13: =IFERROR('Historical Analysis'!D44/'Historical Analysis'!C44-1,0) -> 0.31157616 | E13: =IFERROR('Historical Analysis'!E44/'Historical Analysis'!D44-1,0) -> 0.22496935 | F13: =IFERROR('Historical Analysis'!F44/'Historical Analysis'!E44-1,0) -> 0.057908801 | G13: =IFERROR('Historical Analysis'!G44/'Historical Analysis'!F44-1,0) -> 0.017277892 | H13: =IFERROR('Historical Analysis'!H44/'Historical Analysis'!G44-1,0) -> 0.12845011 | I13: =IFERROR('Historical Analysis'!I44/'Historical Analysis'!H44-1,0) -> 0.25440072 | J13: =IFERROR('Historical Analysis'!J44/'Historical Analysis'!I44-1,0) -> 0.31152811 | K13: =IFERROR('Historical Analysis'!K44/'Historical Analysis'!J44-1,0) -> -0.1572248 | L13: =IFERROR('Historical Analysis'!L44/'Historical Analysis'!K44-1,0) -> 0.069422236 | N13: =IFERROR(AVERAGE(D13:L13),0) -> 0.13536762 | O13: =MEDIAN(D13:L13) -> 0.12845011
B14: Dividend Growth | D14: =IFERROR('Historical Analysis'!D53/'Historical Analysis'!C53-1,0) -> 0.33721253 | E14: =IFERROR('Historical Analysis'!E53/'Historical Analysis'!D53-1,0) -> 1.9739094 | F14: =IFERROR('Historical Analysis'!F53/'Historical Analysis'!E53-1,0) -> -0.41520397 | G14: =IFERROR('Historical Analysis'!G53/'Historical Analysis'!F53-1,0) -> 0 | H14: =IFERROR('Historical Analysis'!H53/'Historical Analysis'!G53-1,0) -> 0.1 | I14: =IFERROR('Historical Analysis'!I53/'Historical Analysis'!H53-1,0) -> -0.20908997 | J14: =IFERROR('Historical Analysis'!J53/'Historical Analysis'!I53-1,0) -> 0.85028222 | K14: =IFERROR('Historical Analysis'!K53/'Historical Analysis'!J53-1,0) -> -0.1614896 | L14: =IFERROR('Historical Analysis'!L53/'Historical Analysis'!K53-1,0) -> -0.11115721 | N14: =IFERROR(AVERAGE(D14:L14),0) -> 0.26271816
B16: Gross Margin | C16: =IFERROR('Historical Analysis'!C16/'Historical Analysis'!C11,0) -> 0.4184423 | D16: =IFERROR('Historical Analysis'!D16/'Historical Analysis'!D11,0) -> 0.44728562 | E16: =IFERROR('Historical Analysis'!E16/'Historical Analysis'!E11,0) -> 0.4337435 | F16: =IFERROR('Historical Analysis'!F16/'Historical Analysis'!F11,0) -> 0.42416609 | G16: =IFERROR('Historical Analysis'!G16/'Historical Analysis'!G11,0) -> 0.42192612 | H16: =IFERROR('Historical Analysis'!H16/'Historical Analysis'!H11,0) -> 0.39505686 | I16: =IFERROR('Historical Analysis'!I16/'Historical Analysis'!I11,0) -> 0.46242138 | J16: =IFERROR('Historical Analysis'!J16/'Historical Analysis'!J11,0) -> 0.4219159 | ... L16: =IFERROR('Historical Analysis'!L16/'Historical Analysis'!L11,0) -> 0.41144999 | N16: =IFERROR(AVERAGE(C16:L16),0) -> 0.4257598 | O16: =MEDIAN(C16:L16) -> 0.42192101
B17: EBITDA Margin | C17: =IFERROR('Historical Analysis'!C24,0) -> 0.20945193 | D17: =IFERROR('Historical Analysis'!D24,0) -> 0.23180902 | E17: =IFERROR('Historical Analysis'!E24,0) -> 0.23655135 | F17: =IFERROR('Historical Analysis'!F24,0) -> 0.2398122 | G17: =IFERROR('Historical Analysis'!G24,0) -> 0.24167282 | H17: =IFERROR('Historical Analysis'!H24,0) -> 0.21934656 | I17: =IFERROR('Historical Analysis'!I24,0) -> 0.23376137 | J17: =IFERROR('Historical Analysis'!J24,0) -> 0.23953211 | ... L17: =IFERROR('Historical Analysis'!L24,0) -> 0.22919679 | N17: =IFERROR(AVERAGE(C17:L17),0) -> 0.23173204 | O17: =MEDIAN(C17:L17) -> 0.23497379
B18: EBIT Margin | C18: =IFERROR('Historical Analysis'!C31/'Historical Analysis'!C11,0) -> 0.19293478 | D18: =IFERROR('Historical Analysis'!D31/'Historical Analysis'!D11,0) -> 0.22501233 | E18: =IFERROR('Historical Analysis'!E31/'Historical Analysis'!E11,0) -> 0.22658523 | F18: =IFERROR('Historical Analysis'!F31/'Historical Analysis'!F11,0) -> 0.22299351 | G18: =IFERROR('Historical Analysis'!G31/'Historical Analysis'!G11,0) -> 0.20752222 | H18: =IFERROR('Historical Analysis'!H31/'Historical Analysis'!H11,0) -> 0.20184341 | I18: =IFERROR('Historical Analysis'!I31/'Historical Analysis'!I11,0) -> 0.21737503 | J18: =IFERROR('Historical Analysis'!J31/'Historical Analysis'!J11,0) -> 0.22277546 | ... L18: =IFERROR('Historical Analysis'!L31/'Historical Analysis'!L11,0) -> 0.20591848 | N18: =IFERROR(AVERAGE(C18:L18),0) -> 0.21498474 | O18: =MEDIAN(C18:L18) -> 0.22007524
B19: EBT Margin (TAX ) | C19: =IFERROR('Historical Analysis'!C38,0) -> 0.1837536 | D19: =IFERROR('Historical Analysis'!D38,0) -> 0.21509847 | E19: =IFERROR('Historical Analysis'!E38,0) -> 0.21614614 | F19: =IFERROR('Historical Analysis'!F38,0) -> 0.21069541 | G19: =IFERROR('Historical Analysis'!G38,0) -> 0.19384027 | H19: =IFERROR('Historical Analysis'!H38,0) -> 0.19269561 | I19: =IFERROR('Historical Analysis'!I38,0) -> 0.21113807 | J19: =IFERROR('Historical Analysis'!J38,0) -> 0.21681126 | ... L19: =IFERROR('Historical Analysis'!L38,0) -> 0.19908139 | N19: =IFERROR(AVERAGE(C19:L19),0) -> 0.2059415 | O19: =MEDIAN(C19:L19) -> 0.21091674
B20: Net Profit Margin | C20: =IFERROR('Historical Analysis'!C45,0) -> 0.12240149 | D20: =IFERROR('Historical Analysis'!D45,0) -> 0.14230354 | E20: =IFERROR('Historical Analysis'!E45,0) -> 0.15914431 | F20: =IFERROR('Historical Analysis'!F45,0) -> 0.15598692 | G20: =IFERROR('Historical Analysis'!G45,0) -> 0.1437127 | H20: =IFERROR('Historical Analysis'!H45,0) -> 0.14147634 | I20: =IFERROR('Historical Analysis'!I45,0) -> 0.15678255 | J20: =IFERROR('Historical Analysis'!J45,0) -> 0.16122234 | ... L20: =IFERROR('Historical Analysis'!L45,0) -> 0.15308405 | N20: =IFERROR(AVERAGE(C20:L20),0) -> 0.15001857 | O20: =MEDIAN(C20:L20) -> 0.15453548
B22: SalesExpenses%Sales ( S& G Margin) | C22: =IFERROR('Historical Analysis'!C19,0) -> 0.18222307 | D22: =IFERROR('Historical Analysis'!D19,0) -> 0.19002557 | E22: =IFERROR('Historical Analysis'!E19,0) -> 0.17997801 | F22: =IFERROR('Historical Analysis'!F19,0) -> 0.16830674 | G22: =IFERROR('Historical Analysis'!G19,0) -> 0.1968795 | H22: =IFERROR('Historical Analysis'!H19,0) -> 0.1889186 | I22: =IFERROR('Historical Analysis'!I19,0) -> 0 | J22: =IFERROR('Historical Analysis'!J19,0) -> 0.19831113 | ... L22: =IFERROR('Historical Analysis'!L19,0) -> 0.20647733 | N22: =IFERROR(AVERAGE(C22:L22),0) -> 0.17153883 | O22: =MEDIAN(C22:L22) -> 0.18947208
B23: Depreciation%Sales | C23: =IFERROR('Historical Analysis'!C29,0) -> 0.034192176 | D23: =IFERROR('Historical Analysis'!D29,0) -> 0.029725644 | E23: =IFERROR('Historical Analysis'!E29,0) -> 0.029925862 | F23: =IFERROR('Historical Analysis'!F29,0) -> 0.027743758 | G23: =IFERROR('Historical Analysis'!G29,0) -> 0.026526754 | H23: =IFERROR('Historical Analysis'!H29,0) -> 0.023851036 | I23: =IFERROR('Historical Analysis'!I29,0) -> 0.022425142 | J23: =IFERROR('Historical Analysis'!J29,0) -> 0.023274271 | ... L23: =IFERROR('Historical Analysis'!L29,0) -> 0.030198319 | N23: =IFERROR(AVERAGE(C23:L23),0) -> 0.027458961 | O23: =MEDIAN(C23:L23) -> 0.027235203
B24: OperatingIncome%Sales | C24: =C18 -> 0.19293478 | D24: =D18 -> 0.22501233 | E24: =E18 -> 0.22658523 | F24: =F18 -> 0.22299351 | G24: =G18 -> 0.20752222 | H24: =H18 -> 0.20184341 | I24: =I18 -> 0.21737503 | J24: =J18 -> 0.22277546 | ... L24: =L18 -> 0.20591848 | N24: =IFERROR(AVERAGE(C24:L24),0) -> 0.21498474 | O24: =MEDIAN(C24:L24) -> 0.22007524
B26: Return on Capital Employed | C26: =IFERROR('Historical Analysis'!C31/SUM('Historical Analysis'!C63:C65),0) -> 0.55883996 | D26: =IFERROR('Historical Analysis'!D31/SUM('Historical Analysis'!D63:D65),0) -> 0.68508552 | E26: =IFERROR('Historical Analysis'!E31/SUM('Historical Analysis'!E63:E65),0) -> 1.3296312 | F26: =IFERROR('Historical Analysis'!F31/SUM('Historical Analysis'!F63:F65),0) -> 1.3738826 | G26: =IFERROR('Historical Analysis'!G31/SUM('Historical Analysis'!G63:G65),0) -> 1.3823864 | H26: =IFERROR('Historical Analysis'!H31/SUM('Historical Analysis'!H63:H65),0) -> 1.2494239 | I26: =IFERROR('Historical Analysis'!I31/SUM('Historical Analysis'!I63:I65),0) -> 1.523096 | J26: =IFERROR('Historical Analysis'!J31/SUM('Historical Analysis'!J63:J65),0) -> 1.4745565 | ... L26: =IFERROR('Historical Analysis'!L31/SUM('Historical Analysis'!L63:L65),0) -> 0.82872041 | N26: =IFERROR(AVERAGE(C26:L26),0) -> 1.1273047 | O26: =MEDIAN(C26:L26) -> 1.2895276
B27: Retained Earnings% | C27: =IFERROR('Historical Analysis'!C57,0) -> 0.32319885 | D27: =IFERROR('Historical Analysis'!D57,0) -> 0.30996994 | E27: =IFERROR('Historical Analysis'!E57,0) -> 0 | F27: =IFERROR('Historical Analysis'!F57,0) -> 0.073966472 | G27: =IFERROR('Historical Analysis'!G57,0) -> 0.089694629 | H27: =IFERROR('Historical Analysis'!H57,0) -> 0.11264495 | I27: =IFERROR('Historical Analysis'!I57,0) -> 0.4405153 | J27: =IFERROR('Historical Analysis'!J57,0) -> 0.21056539 | ... L27: =IFERROR('Historical Analysis'!L57,0) -> 0.34718727 | N27: =IFERROR(AVERAGE(C27:L27),0) -> 0.21223031 | O27: =MEDIAN(C27:L27) -> 0.21256283
B28: Return on Equity% | C28: =IFERROR('Historical Analysis'!C44/SUM('Historical Analysis'!C63:C64),0) -> 0.3581809 | D28: =IFERROR('Historical Analysis'!D44/SUM('Historical Analysis'!D63:D64),0) -> 0.43740983 | E28: =IFERROR('Historical Analysis'!E44/SUM('Historical Analysis'!E63:E64),0) -> 1.0258329 | F28: =IFERROR('Historical Analysis'!F44/SUM('Historical Analysis'!F63:F64),0) -> 1.0312429 | G28: =IFERROR('Historical Analysis'!G44/SUM('Historical Analysis'!G63:G64),0) -> 1.0883846 | H28: =IFERROR('Historical Analysis'!H44/SUM('Historical Analysis'!H63:H64),0) -> 0.97208408 | I28: =IFERROR('Historical Analysis'!I44/SUM('Historical Analysis'!I63:I64),0) -> 1.219383 | J28: =IFERROR('Historical Analysis'!J44/SUM('Historical Analysis'!J63:J64),0) -> 1.1771833 | K28: =IFERROR('Historical Analysis'!K44/SUM('Historical Analysis'!K63:K64),0) -> 0.80504718 | L28: =IFERROR('Historical Analysis'!L44/'Historical Analysis'!L63,0) -> 18.381995 | N28: =IFERROR(AVERAGE(C28:L28),0) -> 2.6496743 | O28: =MEDIAN(C28:L28) -> 1.0285379
B29: Self Sustained Growth Rate | C29: =IFERROR(C28*(1-'Historical Analysis'!C54),0) -> 0.11576365 | D29: =IFERROR(D28*(1-'Historical Analysis'!D54),0) -> 0.1355839 | E29: =IFERROR(E28*(1-'Historical Analysis'!E54),0) -> -0.69265766 | F29: =IFERROR(F28*(1-'Historical Analysis'!F54),0) -> 0.076277398 | G29: =IFERROR(G28*(1-'Historical Analysis'!G54),0) -> 0.097622253 | H29: =IFERROR(H28*(1-'Historical Analysis'!H54),0) -> 0.10950036 | I29: =IFERROR(I28*(1-'Historical Analysis'!I54),0) -> 0.53715685 | J29: =IFERROR(J28*(1-'Historical Analysis'!J54),0) -> 0.24787407 | ... L29: =IFERROR(L28*(1-'Historical Analysis'!L54),0) -> 6.3819945 | N29: =IFERROR(AVERAGE(C29:L29),0) -> 0.71818465 | O29: =MEDIAN(C29:L29) -> 0.12567378
B30: Interest Coverage Ratio ( Ctrl1> custom>0.0"X" | C30: =IFERROR('Historical Analysis'!C31/'Historical Analysis'!C33,0) -> 21.014146 | D30: =IFERROR('Historical Analysis'!D31/'Historical Analysis'!D33,0) -> 22.69674 | E30: =IFERROR('Historical Analysis'!E31/'Historical Analysis'!E33,0) -> 21.705468 | F30: =IFERROR('Historical Analysis'!F31/'Historical Analysis'!F33,0) -> 18.132355 | G30: =IFERROR('Historical Analysis'!G31/'Historical Analysis'!G33,0) -> 15.167592 | H30: =IFERROR('Historical Analysis'!H31/'Historical Analysis'!H33,0) -> 22.064696 | I30: =IFERROR('Historical Analysis'!I31/'Historical Analysis'!I33,0) -> 34.852712 | J30: =IFERROR('Historical Analysis'!J31/'Historical Analysis'!J33,0) -> 37.35212 | ... L30: =IFERROR('Historical Analysis'!L31/'Historical Analysis'!L33,0) -> 30.11787 | N30: =IFERROR(AVERAGE(C30:L30),0) -> 25.680568 | O30: =MEDIAN(C30:L30) -> 22.380718
B31: Self Sustained Growth Rate | C31: =C28*C27 -> 0.11576365 | D31: =D28*D27 -> 0.1355839 | E31: =E28*E27 -> 0 | F31: =F28*F27 -> 0.076277398 | G31: =G28*G27 -> 0.097622253 | H31: =H28*H27 -> 0.10950036 | I31: =I28*I27 -> 0.53715685 | J31: =J28*J27 -> 0.24787407 | ... L31: =L28*L27 -> 6.3819945 | N31: =IFERROR(AVERAGE(C31:L31),0) -> 0.78745041 | O31: =MEDIAN(C31:L31) -> 0.12567378
B33: Debtor Turnover Ratio X - Times payment recived | C33: =IFERROR('Historical Analysis'!C11/'Historical Analysis'!C75,0) -> 112.50534 | D33: =IFERROR('Historical Analysis'!D11/'Historical Analysis'!D75,0) -> 90.635444 | E33: =IFERROR('Historical Analysis'!E11/'Historical Analysis'!E75,0) -> 99.484437 | F33: =IFERROR('Historical Analysis'!F11/'Historical Analysis'!F75,0) -> 80.943612 | G33: =IFERROR('Historical Analysis'!G11/'Historical Analysis'!G75,0) -> 88.814786 | H33: =IFERROR('Historical Analysis'!H11/'Historical Analysis'!H75,0) -> 88.055448 | I33: =IFERROR('Historical Analysis'!I11/'Historical Analysis'!I75,0) -> 99.67325 | J33: =IFERROR('Historical Analysis'!J11/'Historical Analysis'!J75,0) -> 81.188478 | ... L33: =IFERROR('Historical Analysis'!L11/'Historical Analysis'!L75,0) -> 70.278326 | N33: =IFERROR(AVERAGE(C33:L33),0) -> 86.720781 | O33: =MEDIAN(C33:L33) -> 88.435117
B34: Creditor Turnover Ratio | C34: =IFERROR('Historical Analysis'!C11/'Historical Analysis'!C66,0) -> 2.5620575 | D34: =IFERROR('Historical Analysis'!D11/'Historical Analysis'!D66,0) -> 2.5786148 | E34: =IFERROR('Historical Analysis'!E11/'Historical Analysis'!E66,0) -> 2.4419709 | F34: =IFERROR('Historical Analysis'!F11/'Historical Analysis'!F66,0) -> 2.3286696 | G34: =IFERROR('Historical Analysis'!G11/'Historical Analysis'!G66,0) -> 2.4480784 | H34: =IFERROR('Historical Analysis'!H11/'Historical Analysis'!H66,0) -> 2.7039246 | I34: =IFERROR('Historical Analysis'!I11/'Historical Analysis'!I66,0) -> 3.0606732 | J34: =IFERROR('Historical Analysis'!J11/'Historical Analysis'!J66,0) -> 3.5675891 | ... L34: =IFERROR('Historical Analysis'!L11/'Historical Analysis'!L66,0) -> 3.0451473 | N34: =IFERROR(AVERAGE(C34:L34),0) -> 2.760631 | O34: =MEDIAN(C34:L34) -> 2.6412697
B35: Inventory Turnover | C35: =IFERROR('Historical Analysis'!C11/'Historical Analysis'!C76,0) -> 11.091338 | D35: =IFERROR('Historical Analysis'!D11/'Historical Analysis'!D76,0) -> 11.695169 | E35: =IFERROR('Historical Analysis'!E11/'Historical Analysis'!E76,0) -> 9.640082 | F35: =IFERROR('Historical Analysis'!F11/'Historical Analysis'!F76,0) -> 9.4247924 | G35: =IFERROR('Historical Analysis'!G11/'Historical Analysis'!G76,0) -> 9.2553857 | H35: =IFERROR('Historical Analysis'!H11/'Historical Analysis'!H76,0) -> 8.7604847 | I35: =IFERROR('Historical Analysis'!I11/'Historical Analysis'!I76,0) -> 9.9163197 | J35: =IFERROR('Historical Analysis'!J11/'Historical Analysis'!J76,0) -> 11.675293 | ... L35: =IFERROR('Historical Analysis'!L11/'Historical Analysis'!L76,0) -> 9.0123072 | N35: =IFERROR(AVERAGE(C35:L35),0) -> 9.755909 | O35: =MEDIAN(C35:L35) -> 9.5324372
B36: Fixed Asset Turnover | C36: =IFERROR('Historical Analysis'!C11/'Historical Analysis'!C69,0) -> 3.8260364 | D36: =IFERROR('Historical Analysis'!D11/'Historical Analysis'!D69,0) -> 4.7038973 | E36: =IFERROR('Historical Analysis'!E11/'Historical Analysis'!E69,0) -> 5.2825813 | F36: =IFERROR('Historical Analysis'!F11/'Historical Analysis'!F69,0) -> 6.1255248 | G36: =IFERROR('Historical Analysis'!G11/'Historical Analysis'!G69,0) -> 4.9222752 | H36: =IFERROR('Historical Analysis'!H11/'Historical Analysis'!H69,0) -> 5.5514538 | I36: =IFERROR('Historical Analysis'!I11/'Historical Analysis'!I69,0) -> 6.2838979 | J36: =IFERROR('Historical Analysis'!J11/'Historical Analysis'!J69,0) -> 7.0497479 | ... L36: =IFERROR('Historical Analysis'!L11/'Historical Analysis'!L69,0) -> 3.6809307 | N36: =IFERROR(AVERAGE(C36:L36),0) -> 5.1117065 | O36: =MEDIAN(C36:L36) -> 5.1024283
B37: Capital Turnover Ratio | C37: =IFERROR('Historical Analysis'!C11/SUM('Historical Analysis'!C63:C64),0) -> 2.9262788 | D37: =IFERROR('Historical Analysis'!D11/SUM('Historical Analysis'!D63:D64),0) -> 3.0737804 | E37: =IFERROR('Historical Analysis'!E11/SUM('Historical Analysis'!E63:E64),0) -> 6.4459291 | F37: =IFERROR('Historical Analysis'!F11/SUM('Historical Analysis'!F63:F64),0) -> 6.6110858 | G37: =IFERROR('Historical Analysis'!G11/SUM('Historical Analysis'!G63:G64),0) -> 7.5733361 | H37: =IFERROR('Historical Analysis'!H11/SUM('Historical Analysis'!H63:H64),0) -> 6.8710012 | I37: =IFERROR('Historical Analysis'!I11/SUM('Historical Analysis'!I63:I64),0) -> 7.7775428 | J37: =IFERROR('Historical Analysis'!J11/SUM('Historical Analysis'!J63:J64),0) -> 7.3016142 | ... L37: =IFERROR('Historical Analysis'!L11/SUM('Historical Analysis'!L63:L64),0) -> 4.3611892 | N37: =IFERROR(AVERAGE(C37:L37),0) -> 5.7848443 | O37: =MEDIAN(C37:L37) -> 6.5285075
B39: In Days
B40: Debtor Days ( Recievables) | C40: =IFERROR(365/C33,0) -> 3.2442905 | D40: =IFERROR(365/D33,0) -> 4.0271221 | E40: =IFERROR(365/E33,0) -> 3.6689156 | F40: =IFERROR(365/F33,0) -> 4.509312 | G40: =IFERROR(365/G33,0) -> 4.1096761 | H40: =IFERROR(365/H33,0) -> 4.1451155 | I40: =IFERROR(365/I33,0) -> 3.6619655 | J40: =IFERROR(365/J33,0) -> 4.4957118 | ... L40: =IFERROR(365/L33,0) -> 5.1936354 | N40: =IFERROR(AVERAGE(C40:L40),0) -> 4.3617106 | O40: =MEDIAN(C40:L40) -> 4.1273958
B41: Payable Days ( Creditors) | C41: =IFERROR(365/C34,0) -> 142.46362 | D41: =IFERROR(365/D34,0) -> 141.54886 | E41: =IFERROR(365/E34,0) -> 149.46943 | F41: =IFERROR(365/F34,0) -> 156.74186 | G41: =IFERROR(365/G34,0) -> 149.09653 | H41: =IFERROR(365/H34,0) -> 134.98897 | I41: =IFERROR(365/I34,0) -> 119.25481 | J41: =IFERROR(365/J34,0) -> 102.30999 | ... L41: =IFERROR(365/L34,0) -> 119.86284 | N41: =IFERROR(AVERAGE(C41:L41),0) -> 134.2933 | O41: =MEDIAN(C41:L41) -> 138.26892
B42: Inventory Days | C42: =IFERROR(365/C35,0) -> 32.908563 | D42: =IFERROR(365/D35,0) -> 31.209469 | E42: =IFERROR(365/E35,0) -> 37.862749 | F42: =IFERROR(365/F35,0) -> 38.727643 | G42: =IFERROR(365/G35,0) -> 39.436498 | H42: =IFERROR(365/H35,0) -> 41.664362 | I42: =IFERROR(365/I35,0) -> 36.80801 | J42: =IFERROR(365/J35,0) -> 31.262599 | ... L42: =IFERROR(365/L35,0) -> 40.500173 | N42: =IFERROR(AVERAGE(C42:L42),0) -> 38.187614 | O42: =MEDIAN(C42:L42) -> 38.295196
B43: Cash Conversion Cycle (in days) | C43: =SUM(C42,C40)-C41 -> -106.31077 | D43: =SUM(D42,D40)-D41 -> -106.31227 | E43: =SUM(E42,E40)-E41 -> -107.93777 | F43: =SUM(F42,F40)-F41 -> -113.5049 | G43: =SUM(G42,G40)-G41 -> -105.55036 | H43: =SUM(H42,H40)-H41 -> -89.179494 | I43: =SUM(I42,I40)-I41 -> -78.784833 | J43: =SUM(J42,J40)-J41 -> -66.551677 | ... L43: =SUM(L42,L40)-L41 -> -74.169029 | N43: =IFERROR(AVERAGE(C43:L43),0) -> -91.743978 | O43: =MEDIAN(C43:L43) -> -97.364926
B45: Cash from Operations - Cash flow
B46: CFO/Sales | C46: =IFERROR('Historical Analysis'!C96/'Historical Analysis'!C11,0) -> 0.2171915 | D46: =IFERROR('Historical Analysis'!D96/'Historical Analysis'!D11,0) -> 0.24769156 | E46: =IFERROR('Historical Analysis'!E96/'Historical Analysis'!E11,0) -> 0.27059803 | F46: =IFERROR('Historical Analysis'!F96/'Historical Analysis'!F11,0) -> 0.2344564 | G46: =IFERROR('Historical Analysis'!G96/'Historical Analysis'!G11,0) -> 0.22081884 | H46: =IFERROR('Historical Analysis'!H96/'Historical Analysis'!H11,0) -> 0.16517764 | I46: =IFERROR('Historical Analysis'!I96/'Historical Analysis'!I11,0) -> 0.18550373 | J46: =IFERROR('Historical Analysis'!J96/'Historical Analysis'!J11,0) -> 0.18508733 | ... L46: =IFERROR('Historical Analysis'!L96/'Historical Analysis'!L11,0) -> 0.13725135 | N46: =IFERROR(AVERAGE(C46:L46),0) -> 0.21223703 | O46: =MEDIAN(C46:L46) -> 0.21900517
B47: CFO/Total Assets | C47: =IFERROR('Historical Analysis'!C96/'Historical Analysis'!C80,0) -> 0.29527653 | D47: =IFERROR('Historical Analysis'!D96/'Historical Analysis'!D80,0) -> 0.34581755 | E47: =IFERROR('Historical Analysis'!E96/'Historical Analysis'!E80,0) -> 0.46661481 | F47: =IFERROR('Historical Analysis'!F96/'Historical Analysis'!F80,0) -> 0.39621607 | G47: =IFERROR('Historical Analysis'!G96/'Historical Analysis'!G80,0) -> 0.39530588 | H47: =IFERROR('Historical Analysis'!H96/'Historical Analysis'!H80,0) -> 0.3108454 | I47: =IFERROR('Historical Analysis'!I96/'Historical Analysis'!I80,0) -> 0.39515567 | J47: =IFERROR('Historical Analysis'!J96/'Historical Analysis'!J80,0) -> 0.42905771 | ... L47: =IFERROR('Historical Analysis'!L96/'Historical Analysis'!L80,0) -> 0.23792465 | N47: =IFERROR(AVERAGE(C47:L47),0) -> 0.36961064 | O47: =MEDIAN(C47:L47) -> 0.39523077
B48: CFO/Total Debt | C48: =IFERROR('Historical Analysis'!C96/'Historical Analysis'!C65,0) -> 61.866818 | D48: =IFERROR('Historical Analysis'!D96/'Historical Analysis'!D65,0) -> 79.595902 | E48: =IFERROR('Historical Analysis'!E96/'Historical Analysis'!E65,0) -> 17.714618 | F48: =IFERROR('Historical Analysis'!F96/'Historical Analysis'!F65,0) -> 21.221778 | G48: =IFERROR('Historical Analysis'!G96/'Historical Analysis'!G65,0) -> 12.215717 | H48: =IFERROR('Historical Analysis'!H96/'Historical Analysis'!H65,0) -> 10.317167 | I48: =IFERROR('Historical Analysis'!I96/'Historical Analysis'!I65,0) -> 13.115481 | J48: =IFERROR('Historical Analysis'!J96/'Historical Analysis'!J65,0) -> 13.104809 | ... L48: =IFERROR('Historical Analysis'!L96/'Historical Analysis'!L65,0) -> 7.1550793 | N48: =IFERROR(AVERAGE(C48:L48),0) -> 24.078438 | O48: =MEDIAN(C48:L48) -> 13.110145

Sheet Nestle - Forecasting
B7: ='Data Sheet'!B1&" - " &'Data Sheet'!A17 &" Forecasting" -> NESTLE INDIA LTD - Sales Forecasting | H7: ='Data Sheet'!B1 &" - " &'Data Sheet'!A18&" Forecasting" -> NESTLE INDIA LTD - Raw Material Cost Forecasting | M7: ='Data Sheet'!B1& " - " &'Data Sheet'!A28& " Forecasting" -> NESTLE INDIA LTD - Profit before tax Forecasting
A8: # | B8: Year Weight | C8: Year | D8: Sales | E8: Sales Growth | H8: Year Weight | I8: Year | J8: COGS | K8: COGS Growth | M8: Year Weight | N8: Year | O8: PBT | P8: PBT Growth
B9: 1 | C9: ='Data Sheet'!B16 -> 43100 | D9: {=TRANSPOSE('Data Sheet'!B17:K17)} -> 10009.6 | H9: 1 | I9: 43100 | J9: {=TRANSPOSE('Data Sheet'!B18:K18)} -> 3696.99 | M9: 1 | N9: 43100 | O9: {=TRANSPOSE('Data Sheet'!B28:K28)} -> 1839.3
B10: =B9+1 -> 2 | C10: =365+C9 -> 43465 | D10: 11292.27 | E10: =D10/D9-1 -> 0.12814398 | H10: 2 | I10: 43465 | J10: 3829.22 | K10: =J10/J9-1 -> 0.035766935 | M10: 2 | N10: 43465 | O10: 2428.95 | P10: =O10/O9-1 -> 0.32058392
B11: =B10+1 -> 3 | C11: =365+C10 -> 43830 | D11: 12368.9 | E11: =D11/D10-1 -> 0.095342212 | H11: 3 | I11: 43830 | J11: 4520.91 | K11: =J11/J10-1 -> 0.1806347 | M11: 3 | N11: 43830 | O11: 2673.49 | P11: =O11/O10-1 -> 0.10067725
B12: =B11+1 -> 4 | C12: =365+C11 -> 44195 | D12: 13350.03 | E12: =D12/D11-1 -> 0.079322333 | H12: 4 | I12: 44195 | J12: 4901.74 | K12: =J12/J11-1 -> 0.084237465 | M12: 4 | N12: 44195 | O12: 2812.79 | P12: =O12/O11-1 -> 0.052104178
B13: =B12+1 -> 5 | C13: =365+C12 -> 44560 | D13: 14740.59 | E13: =D13/D12-1 -> 0.10416156 | H13: 5 | I13: 44560 | J13: 5301.26 | K13: =J13/J12-1 -> 0.081505751 | M13: 5 | N13: 44560 | O13: 2857.32 | P13: =O13/O12-1 -> 0.015831257
B14: =B13+1 -> 6 | C14: =365+C13 -> 44925 | D14: 16896.96 | E14: =D14/D13-1 -> 0.1462879 | H14: 6 | I14: 44925 | J14: 6660.42 | K14: =J14/J13-1 -> 0.25638433 | M14: 6 | N14: 44925 | O14: 3255.97 | P14: =O14/O13-1 -> 0.13951885
B15: =B14+1 -> 7 | C15: =365+C14 -> 45290 | D15: 19126.3 | E15: =D15/D14-1 -> 0.13193734 | H15: 7 | I15: 45290 | J15: 8472.72 | K15: =J15/J14-1 -> 0.27209996 | M15: 7 | N15: 45290 | O15: 4038.29 | P15: =O15/O14-1 -> 0.24027248
B16: =B15+1 -> 8 | C16: =365+C15 -> 45655 | D16: 24393.89 | E16: =D16/D15-1 -> 0.27541082 | H16: 8 | I16: 45655 | J16: 9201.11 | K16: =J16/J15-1 -> 0.085968851 | M16: 8 | N16: 45655 | O16: 5288.87 | P16: =O16/O15-1 -> 0.30968058
B17: =B16+1 -> 9 | C17: =365+C16 -> 46020 | D17: 20201.56 | E17: =D17/D16-1 -> -0.17185984 | H17: 9 | I17: 46020 | J17: 7646.63 | K17: =J17/J16-1 -> -0.16894483 | M17: 9 | N17: 46020 | O17: 4447.47 | P17: =O17/O16-1 -> -0.1590888
B18: =B17+1 -> 10 | C18: =365+C17 -> 46385 | D18: 23154.6 | E18: =D18/D17-1 -> 0.14617881 | H18: 10 | I18: 46385 | J18: 9113.96 | K18: =J18/J17-1 -> 0.19189238 | M18: 10 | N18: 46385 | O18: 4609.65 | P18: =O18/O17-1 -> 0.036465676
B19: =B18+1 -> 11 | C19: =365+C18 -> 46750 | D19: =FORECAST(B19,$D$9:$D$18,$B$9:$B$18) -> 25229.475 | E19: =D19/D18-1 -> 0.089609638 | H19: 11 | I19: 46750 | J19: =FORECAST(H19,$J$9:$J$18,$H$9:$H$18) -> 10032.753 | K19: =J19/J18-1 -> 0.10081158 | M19: 11 | N19: 46750 | O19: =FORECAST(M19,$O$9:$O$18,$M$9:$M$18) -> 5299.038 | P19: =O19/O18-1 -> 0.14955322
B20: =B19+1 -> 12 | C20: =365+C19 -> 47115 | D20: =FORECAST(B20,$D$9:$D$18,$B$9:$B$18) -> 26806.931 | E20: =D20/D19-1 -> 0.062524309 | H20: 12 | I20: 47115 | J20: =FORECAST(H20,$J$9:$J$18,$H$9:$H$18) -> 10705.163 | K20: =J20/J19-1 -> 0.067021517 | M20: 12 | N20: 47115 | O20: =FORECAST(M20,$O$9:$O$18,$M$9:$M$18) -> 5639.734 | P20: =O20/O19-1 -> 0.064293934
B21: =B20+1 -> 13 | C21: =365+C20 -> 47480 | D21: =FORECAST(B21,$D$9:$D$18,$B$9:$B$18) -> 28384.386 | E21: =D21/D20-1 -> 0.058845062 | H21: 13 | I21: 47480 | J21: =FORECAST(H21,$J$9:$J$18,$H$9:$H$18) -> 11377.573 | K21: =J21/J20-1 -> 0.062811776 | M21: 13 | N21: 47480 | O21: =FORECAST(M21,$O$9:$O$18,$M$9:$M$18) -> 5980.43 | P21: =O21/O20-1 -> 0.060409941
B22: =B21+1 -> 14 | C22: =365+C21 -> 47845 | D22: =FORECAST(B22,$D$9:$D$18,$B$9:$B$18) -> 29961.842 | E22: =D22/D21-1 -> 0.055574762 | H22: 14 | I22: 47845 | J22: =FORECAST(H22,$J$9:$J$18,$H$9:$H$18) -> 12049.984 | K22: =J22/J21-1 -> 0.059099624 | M22: 14 | N22: 47845 | O22: =FORECAST(M22,$O$9:$O$18,$M$9:$M$18) -> 6321.126 | P22: =O22/O21-1 -> 0.056968479
B23: =B22+1 -> 15 | C23: =365+C22 -> 48210 | D23: =FORECAST(B23,$D$9:$D$18,$B$9:$B$18) -> 31539.297 | E23: =D23/D22-1 -> 0.052648817 | H23: 15 | I23: 48210 | J23: =FORECAST(H23,$J$9:$J$18,$H$9:$H$18) -> 12722.394 | K23: =J23/J22-1 -> 0.055801761 | M23: 15 | N23: 48210 | O23: =FORECAST(M23,$O$9:$O$18,$M$9:$M$18) -> 6661.822 | P23: =O23/O22-1 -> 0.053897992
A27: #

Sheet Beta - FMCG
B5: Nestlee Weekly Returns | G5: Nifty 50 Weekly Returns
B7: Date | C7: Price | D7: Weekly returns | G7: Date | H7: Price | I7: Weekly returns
B8: 46208 | C8: 1455.2 | G8: 46208 | H8: 49350.15 | L8: 3 Ways to calculate Beta:
B9: 46201 | C9: 1457.8 | D9: =C9/C8-1 -> 0.001786696 | G9: 46201 | H9: 50096.4 | I9: =H9/H8-1 -> 0.015121535
B10: 46194 | C10: 1400.68 | D10: =C10/C9-1 -> -0.03918233 | G10: 46194 | H10: 49419.25 | I10: =H10/H9-1 -> -0.013516939 | L10: Beta1 | M10: =SLOPE(D9:D59,I9:I59) -> 1.162631
B11: 46187 | C11: 1412.87 | D11: =C11/C10-1 -> 0.0087029157 | G11: 46187 | H11: 49558.7 | I11: =H11/H10-1 -> 0.0028217749 | L11: Beta2 | M11: =M32 -> 1.162631
B12: 46180 | C12: 1373.82 | D12: =C12/C11-1 -> -0.027638778 | G12: 46180 | H12: 48827.6 | I12: =H12/H11-1 -> -0.014752203 | L12: Beta3 | M12: =_xlfn.COVARIANCE.S(D9:D59,I9:I59)/_xlfn.VAR.P(I9:I59) -> 1.1858836
B13: 46173 | C13: 1386.2 | D13: =C13/C12-1 -> 0.0090113698 | G13: 46173 | H13: 48302.45 | I13: =H13/H12-1 -> -0.010755188
B14: 46166 | C14: 1421.5 | D14: =C14/C13-1 -> 0.025465301 | G14: 46166 | H14: 49383.35 | I14: =H14/H13-1 -> 0.022377747
B15: 46159 | C15: 1423.1 | D15: =C15/C14-1 -> 0.0011255716 | G15: 46159 | H15: 50249.8 | I15: =H15/H14-1 -> 0.017545387 | L15: SUMMARY OUTPUT
B16: 46152 | C16: 1430.5 | D16: =C16/C15-1 -> 0.0051999157 | G16: 46152 | H16: 51051.35 | I16: =H16/H15-1 -> 0.015951307
B17: 46145 | C17: 1482.4 | D17: =C17/C16-1 -> 0.036281021 | G17: 46145 | H17: 51165.9 | I17: =H17/H16-1 -> 0.0022438192 | L17: Regression Statistics
B18: 46138 | C18: 1458.6 | D18: =C18/C17-1 -> -0.016055046 | G18: 46138 | H18: 51072.1 | I18: =H18/H17-1 -> -0.0018332522 | L18: Multiple R | M18: 0.68042859
B19: 46131 | C19: 1421.3 | D19: =C19/C18-1 -> -0.025572467 | G19: 46131 | H19: 50766.25 | I19: =H19/H18-1 -> -0.0059885926 | L19: R Square | M19: 0.46298306
B20: 46124 | C20: 1285.6 | D20: =C20/C19-1 -> -0.095475973 | G20: 46124 | H20: 49657.75 | I20: =H20/H19-1 -> -0.021835373 | L20: Adjusted R Square | M20: 0.45202353
B21: 46117 | C21: 1249.3 | D21: =C21/C20-1 -> -0.028235843 | G21: 46117 | H21: 48194.05 | I21: =H21/H20-1 -> -0.029475762 | L21: Standard Error | M21: 0.022218089
B22: 46110 | C22: 1191.3 | D22: =C22/C21-1 -> -0.046425999 | G22: 46110 | H22: 46232.15 | I22: =H22/H21-1 -> -0.040708345 | L22: Observations | M22: 51
B23: 46103 | C23: 1193.2 | D23: =C23/C22-1 -> 0.0015948963 | G23: 46103 | H23: 46427.2 | I23: =H23/H22-1 -> 0.0042189256
B24: 46096 | C24: 1193.6 | D24: =C24/C23-1 -> 0.00033523299 | G24: 46096 | H24: 47007.55 | I24: =H24/H23-1 -> 0.012500215 | L24: ANOVA
B25: 46089 | C25: 1202.2 | D25: =C25/C24-1 -> 0.0072050938 | G25: 46089 | H25: 47924.15 | I25: =H25/H24-1 -> 0.019498995 | M25: df | N25: SS | O25: MS | P25: F | Q25: Significance F
